<?xml version="1.0"?>

<robot name="catbot" xmlns:xacro="http://www.ros.org/wiki/xacro">
<xacro:include filename="$(find rl_walker_description)/urdf/main.gazebo" />


<link name="base_footprint">
<inertial>
    <origin xyz="0.0 0.0 0.0" rpy="0 0 0" />
    <mass value="0.3" />
    <inertia ixx="0.000000001" ixy="0.000000001" ixz="0.000000001" iyy="0.000000001" iyz="0.000000001" izz="0.000000001"/>
</inertial>
<visual>
    <origin xyz="0 0 0" rpy="0 0 0" />
    <geometry>
     <cylinder length="0.001" radius="0.001" />
    </geometry>
</visual>
<collision>
<origin xyz="0 0.0 0" rpy="0 0 0" />
    <geometry>
     <cylinder length="0.001" radius="0.001" />
    </geometry>
</collision>
</link>





<link name="base_body">
<inertial>
    <origin xyz="0.0 0.0 0.5" rpy="0 0 0" />
    <mass value="3.0" />
    <inertia ixx="0.42841" ixy="-2.3739" ixz="0.00227" iyy="0.43178" iyz="1.46390" izz="0.08742"/>
</inertial>
<visual>
    <origin xyz="0 0 0" rpy="0 0 0" />
    <geometry>
    <mesh filename="package://rl_walker_description/meshes/dae/body.dae" scale="1 1 1" />
    </geometry>
</visual>
<collision>
<origin xyz="0 0.0 0" rpy="0 0 0" />
    <geometry>
    <mesh filename="package://rl_walker_description/meshes/dae/body.dae" scale="1 1 1" />
    </geometry>
</collision>
</link>


<joint name="base_joint" type="fixed">
    <axis xyz="0 0 0" />
    <origin xyz="0 0 0.80" rpy="0 0 0" />
    <parent link="base_footprint" />
    <child link="base_body" />
</joint>

<!-- ##########################################################
     ######################### left leg ########################
     ########################################################## -->


<joint
    name="bum_zlj" type="revolute">
    <origin xyz="-0.02 0.265 0.16" rpy="0 -0.3 0" />
    <parent link="base_body" />
    <child link="bum_zl" />
    <axis xyz="0 0 1" />
    <limit lower="-0.345" upper="0.345" effort="20" velocity="3"/>
    <!-- dynamics damping="5" friction="0.0"/ -->
</joint>

<link name="bum_zl">
<inertial>
    <origin xyz="0.0 0.0 -0.19" rpy="0 0 0" />
    <mass value="0.3" />
    <inertia ixx="0.000000001" ixy="0.000000001" ixz="0.000000001" iyy="0.000000001" iyz="0.000000001" izz="0.000000001"/>
</inertial>
<visual>
    <origin xyz="0 0 0" rpy="0 0 1.571" />
    <geometry>
    <cylinder length="0.001" radius="0.001" />
    </geometry>
</visual>
<collision>
<origin xyz="0 0.0 0" rpy="0 0 1.571" />
    <geometry>
    <cylinder length="0.001" radius="0.001" />
    </geometry>
</collision>
</link>




<joint
    name="bum_xlj" type="revolute">
    <origin xyz="0 0 0" rpy="0 0 0" />
    <parent link="bum_zl" />
    <child link="bum_xl" />
    <axis xyz="1 0 0" />
    <limit lower="-0.345" upper="1" effort="20" velocity="3"/>
    <!-- dynamics damping="5" friction="0.0"/ -->
</joint>

<link name="bum_xl">
<inertial>
    <origin xyz="0.0 0.0 -0.19" rpy="0 0 0" />
    <mass value="0.3" />
    <inertia ixx="0.000000001" ixy="0.000000001" ixz="0.000000001" iyy="0.000000001" iyz="0.000000001" izz="0.000000001"/>
</inertial>
<visual>
    <origin xyz="0 0 0" rpy="0 0 1.571" />
    <geometry>
    <cylinder length="0.001" radius="0.001" />
    </geometry>
</visual>
<collision>
<origin xyz="0 0.0 0" rpy="0 0 1.571" />
    <geometry>
    <cylinder length="0.001" radius="0.001" />
    </geometry>
</collision>
</link>



<joint
    name="bum_ylj" type="revolute">
    <!-- <origin xyz="0 0 0" rpy="0 0.35 3.142" /> -->
    <origin xyz="0 0 0" rpy="0 0 3.142" />
    <parent link="bum_xl" />
    <child link="left_hip" />
    <axis xyz="0 1 0" />
    <limit lower="0" upper="1" effort="20" velocity="3"/>
    <!-- dynamics damping="5" friction="0.0"/ -->
</joint>




<link name="left_hip">
<inertial>
    <origin xyz="0.0 0 -0.19" rpy="0 0 0" />
    <mass value="0.3" />
    <inertia ixx="0.31319" ixy="-1.5919" ixz="0.00039" iyy="0.314057" iyz="-0.00060" izz="0.02458"/>
</inertial>
<visual>
    <origin xyz="0 0 0" rpy="0 0 1.571" />
    <geometry>
    <mesh filename="package://rl_walker_description/meshes/dae/hip.dae" scale="1 1 1" />
    </geometry>
</visual>
<collision>
<origin xyz="0 0.0 0" rpy="0 0 1.571" />
    <geometry>
    <mesh filename="package://rl_walker_description/meshes/dae/hip.dae" scale="1 1 1" />
    </geometry>
</collision>
</link>



<joint
    name="knee_left" type="revolute">
    <origin xyz="0 0 -0.335" rpy="0 -0.5 0" />
    <parent link="left_hip" />
    <child link="left_shin" />
    <axis xyz="0 1 0" />
    <limit lower="-1.3" upper="0" effort="20" velocity="3"/>
    <!-- dynamics damping="5" friction="0.0"/ -->
</joint>




<link name="left_shin">
<inertial>
    <origin xyz="0.0 0.0 -0.2" rpy="0 0 0" />
    <mass value="0.3" />
    <inertia ixx="0.283162" ixy="0.00034" ixz="0.001493" iyy="0.284290" iyz="0.000595" izz="0.0277465"/>
</inertial>
<visual>
    <origin xyz="0 0 0" rpy="0 0 1.571" />
    <geometry>
    <mesh filename="package://rl_walker_description/meshes/dae/shin.dae" scale="1 1 1" />
    </geometry>
</visual>
<collision>
<origin xyz="0 0.0 0" rpy="0 0 1.571" />
    <geometry>
    <mesh filename="package://rl_walker_description/meshes/dae/shin.dae" scale="1 1 1" />
    </geometry>
</collision>
</link>



<!-- 
<joint
    name="ankle_lj" type="revolute">
    <origin xyz="0 0 -0.58" rpy="0 0.3 0" />
    <parent link="left_shin" />
    <child link="left_ankle" />
    <axis xyz="0 1 0" />
    <limit lower="-1.3" upper="0.3" effort="20" velocity="3"/>
</joint>




<link name="left_ankle">
<inertial>
    <origin xyz="0.0 0.0 0.0" rpy="0 0 0" />
    <mass value="0.3" />
    <inertia ixx="0.119924" ixy="-0.0003874" ixz="-0.0010433" iyy="0.166674" iyz="5.8010177" izz="0.1314669"/>
</inertial>
<visual>
    <origin xyz="-0.06 0 0" rpy="0 0 3.142" />
    <geometry>
    <mesh filename="package://rl_walker_description/meshes/dae/ankle.dae" scale="1 1 1" />
    </geometry>
</visual>
<collision>
<origin xyz="-0.06 0.0 0" rpy="0 0 3.142" />
    <geometry>
    <mesh filename="package://rl_walker_description/meshes/dae/ankle.dae" scale="1 1 1" />
    </geometry>
</collision>
</link> -->


<joint
    name="foot_lj" type="revolute">
    <origin xyz="0 0 -0.57" rpy="0 0.21 0" />
    <parent link="left_shin" />
    <child link="left_foot" />
    <axis xyz="0 1 0" />
    <limit lower="-0.4" upper="0.7" effort="20" velocity="3"/>
</joint>




<link name="left_foot">
<inertial>
    <origin xyz="0.0 0.0 0" rpy="0 0 0" />
    <mass value="1.5" />
    <inertia ixx="0.10917" ixy="1.3005" ixz="-0.01020" iyy="0.15687" iyz="3.44815" izz="0.1"/>
</inertial>
<visual>
    <origin xyz="-0.03 0 -0.05" rpy="0 0 3.142" />
    <geometry>
    <mesh filename="package://rl_walker_description/meshes/dae/new_foot.dae" scale="1 1 1" />
    </geometry>
</visual>
<collision>
<origin xyz="-0.03 0.0 -0.05" rpy="0 0 3.142" />
    <geometry>
    <mesh filename="package://rl_walker_description/meshes/dae/new_foot.dae" scale="1 1 1" />
    </geometry>
</collision>
</link>




<joint
    name="contact_lj" type="fixed">
    <origin xyz="0.01 0 -0.155" rpy="0 0 0" />
    <parent link="left_foot" />
    <child link="left_leg_contact_sensor" />
    <axis xyz="0 1 0" />
    <!-- <limit lower="-0.4" upper="0.7" effort="20" velocity="3"/> -->
    <!-- dynamics damping="5" friction="0.0"/ -->
</joint>




<link name="left_leg_contact_sensor">
<inertial >
            <origin xyz="0 0 0" rpy="0 0 0"/>
            <mass value="0.01" />
            <inertia ixx="1.28e-06" ixy="0.0" ixz="0.0" iyy="1.28e-06" iyz="0.0" izz="1.28e-06"/>
        </inertial>
        <collision>
            <origin xyz="0 0 0" rpy="0 0 0"/>
            <geometry>
                <!--
                <sphere radius="0.030"/>
                -->
                <box size="0.3 0.2 0.015"/>
                
                <!-- <sphere radius="0.01"/> -->
            </geometry>
        </collision>
        <visual>
            <origin rpy="0.0 0 0" xyz="0 0 0"/>
            <geometry>
                <!--
                <sphere radius="0.030"/>
                -->
                <box size="0.3 0.2 0.015"/>
                
                <!-- <sphere radius="0.01"/> -->
            </geometry>
        </visual>
</link>











<!-- ##########################################################
     ######################### right leg ########################
     ########################################################## -->


<joint
    name="bum_zrj" type="revolute">
    <origin xyz="-0.02 -0.265 0.16" rpy="0 -0.3 0" />
    <parent link="base_body" />
    <child link="bum_zr" />
    <axis xyz="0 0 1" />
    <limit lower="-0.345" upper="0.345" effort="20" velocity="3"/>
    <!-- dynamics damping="5" friction="0.0"/ -->
</joint>

<link name="bum_zr">
<inertial>
    <origin xyz="0.0 0.0 -0.19" rpy="0 0 0" />
    <mass value="0.3" />
    <inertia ixx="0.000000001" ixy="0.000000001" ixz="0.000000001" iyy="0.000000001" iyz="0.000000001" izz="0.000000001"/>
</inertial>
<visual>
    <origin xyz="0 0 0" rpy="0 0 1.571" />
    <geometry>
    <cylinder length="0.001" radius="0.001" />
    </geometry>
</visual>
<collision>
<origin xyz="0 0.0 0" rpy="0 0 1.571" />
    <geometry>
    <cylinder length="0.001" radius="0.001" />
    </geometry>
</collision>
</link>



<joint
    name="bum_xrj" type="revolute">
    <origin xyz="0 0 0" rpy="0 0 0" />
    <parent link="bum_zr" />
    <child link="bum_xr" />
    <axis xyz="1 0 0" />
    <limit lower="-1" upper="0.345" effort="20" velocity="3"/>
    <!-- dynamics damping="5" friction="0.0"/ -->
</joint>

<link name="bum_xr">
<inertial>
    <origin xyz="0.0 0.0 -0.19" rpy="0 0 0" />
    <mass value="0.3" />
    <inertia ixx="0.000000001" ixy="0.000000001" ixz="0.000000001" iyy="0.000000001" iyz="0.000000001" izz="0.000000001"/>
</inertial>
<visual>
    <origin xyz="0 0 0" rpy="0 0 1.571" />
    <geometry>
    <cylinder length="0.001" radius="0.001" />
    </geometry>
</visual>
<collision>
<origin xyz="0 0.0 0" rpy="0 0 1.571" />
    <geometry>
    <cylinder length="0.001" radius="0.001" />
    </geometry>
</collision>
</link>


<joint
    name="bum_yrj" type="revolute">
    <origin xyz="0 0 0" rpy="0 0 3.142" />
    <parent link="bum_xr" />
    <child link="right_hip" />
    <axis xyz="0 1 0" />
    <limit lower="0" upper="1" effort="20" velocity="3"/>
    <!-- dynamics damping="5" friction="0.0"/ -->
</joint>


<link name="right_hip">
<inertial>
    <origin xyz="0.0 0 -0.19" rpy="0 0 0" />
    <mass value="0.3" />
    <inertia ixx="0.31319" ixy="-1.5919" ixz="0.00039" iyy="0.314057" iyz="-0.00060" izz="0.02458"/>
</inertial>
<visual>
    <origin xyz="0 0 0" rpy="0 0 1.571" />
    <geometry>
    <mesh filename="package://rl_walker_description/meshes/dae/hip.dae" scale="1 1 1" />
    </geometry>
</visual>
<collision>
<origin xyz="0 0.0 0" rpy="0 0 1.571" />
    <geometry>
    <mesh filename="package://rl_walker_description/meshes/dae/hip.dae" scale="1 1 1" />
    </geometry>
</collision>
</link>

<joint
    name="knee_right" type="revolute">
    <origin xyz="0 0 -0.335" rpy="0 -0.5 0" />
    <parent link="right_hip" />
    <child link="right_shin" />
    <axis xyz="0 1 0" />
    <limit lower="-1.3" upper="0" effort="20" velocity="3"/>
    <!-- dynamics damping="5" friction="0.0"/ -->
</joint>




<link name="right_shin">
<inertial>
    <origin xyz="0.0 0.0 -0.2" rpy="0 0 0" />
    <mass value="0.3" />
    <inertia ixx="0.283162" ixy="0.00034" ixz="0.001493" iyy="0.284290" iyz="0.000595" izz="0.0277465"/>
</inertial>
<visual>
    <origin xyz="0 0 0" rpy="0 0 1.571" />
    <geometry>
    <mesh filename="package://rl_walker_description/meshes/dae/shin.dae" scale="1 1 1" />
    </geometry>
</visual>
<collision>
<origin xyz="0 0.0 0" rpy="0 0 1.571" />
    <geometry>
    <mesh filename="package://rl_walker_description/meshes/dae/shin.dae" scale="1 1 1" />
    </geometry>
</collision>
</link>



<!-- <joint
    name="ankle_rj" type="revolute">
    <origin xyz="0 0 -0.58" rpy="0 0.3 0" />
    <parent link="right_shin" />
    <child link="right_ankle" />
    <axis xyz="0 1 0" />
    <limit lower="-1.3" upper="0.3" effort="20" velocity="3"/>
</joint>




<link name="right_ankle">
<inertial>
    <origin xyz="0.0 0.0 0.0" rpy="0 0 0" />
    <mass value="0.3" />
    <inertia ixx="0.119924" ixy="-0.0003874" ixz="-0.0010433" iyy="0.166674" iyz="5.8010177" izz="0.1314669"/>
</inertial>
<visual>
    <origin xyz="-0.06 0 0" rpy="0 0 3.142" />
    <geometry>
    <mesh filename="package://rl_walker_description/meshes/dae/ankle.dae" scale="1 1 1" />
    </geometry>
</visual>
<collision>
<origin xyz="-0.06 0.0 0" rpy="0 0 3.142" />
    <geometry>
    <mesh filename="package://rl_walker_description/meshes/dae/ankle.dae" scale="1 1 1" />
    </geometry>
</collision>
</link> -->


<joint
    name="foot_rj" type="revolute">
    <origin xyz="0 0 -0.57" rpy="0 0.21 0" />
    <parent link="right_shin" />
    <child link="right_foot" />
    <axis xyz="0 1 0" />
    <limit lower="-0.4" upper="0.7" effort="20" velocity="3"/>
    <!-- dynamics damping="5" friction="0.0"/ -->
</joint>




<link name="right_foot">
<inertial>
    <origin xyz="0.0 0.0 0.0" rpy="0 0 0" />
    <mass value="1.5" />
    <inertia ixx="0.119924" ixy="-0.0003874" ixz="-0.0010433" iyy="0.166674" iyz="5.8010177" izz="0.1314669"/>
</inertial>
<visual>
    <origin xyz="-0.03 0.0 -0.05" rpy="0 0 3.142" />
    <geometry>
    <mesh filename="package://rl_walker_description/meshes/dae/new_foot.dae" scale="1 1 1" />
    </geometry>
</visual>
<collision>
<origin xyz="-0.03 0.0 -0.05" rpy="0 0 3.142" />
    <geometry>
    <mesh filename="package://rl_walker_description/meshes/dae/new_foot.dae" scale="1 1 1" />
    </geometry>
</collision>
</link>





<joint
    name="contact_rj" type="fixed">
    <origin xyz="0.01 0 -0.155" rpy="0 0 0" />
    <parent link="right_foot" />
    <child link="right_leg_contact_sensor" />
    <axis xyz="0 1 0" />
    <!-- <limit lower="-" upper="0.7" effort="20" velocity="3"/> -->
    <!-- dynamics damping="5" friction="0.0"/ -->
</joint>




<link name="right_leg_contact_sensor">
<inertial >
            <origin xyz="0 0 0" rpy="0 0 0"/>
            <mass value="0.01" />
            <inertia ixx="1.28e-06" ixy="0.0" ixz="0.0" iyy="1.28e-06" iyz="0.0" izz="1.28e-06"/>
        </inertial>
        <collision>
            <origin xyz="0 0 0" rpy="0 0 0"/>
            <geometry>
                <!--
                <sphere radius="0.030"/>
                -->
                <box size="0.3 0.2 0.015"/>
                
                <!-- <sphere radius="0.01"/> -->
            </geometry>
        </collision>
        <visual>
            <origin rpy="0.0 0 0" xyz="0 0 0"/>
            <geometry>
                <!--
                <sphere radius="0.030"/>
                -->
                <box size="0.3 0.2 0.015"/>
                
                <!-- <sphere radius="0.01"/> -->
            </geometry>
        </visual>
</link>




<!-- ##########################################################
     ######################### right hand ########################
     ########################################################## -->

<!-- <joint
    name="shoulder_zrj" type="revolute">
    <origin xyz="0 -0.3 0.87" rpy="0 0 0" />
    <parent link="base_body" />
    <child link="shoulder_zr" />
    <axis xyz="0 0 1" />
    <limit lower="-0.345" upper="1.65" effort="20" velocity="3"/>
</joint>

<link name="shoulder_zr">
<inertial>
    <origin xyz="0.0 0.0 0.0" rpy="0 0 0" />
    <mass value="0.1" />
    <inertia ixx="0.000000001" ixy="0.000000001" ixz="0.000000001" iyy="0.000000001" iyz="0.000000001" izz="0.000000001"/>
</inertial>
<visual>
    <origin xyz="0 0 0" rpy="0 0 1.571" />
    <geometry>
    <cylinder length="0.001" radius="0.001" />
    </geometry>
</visual>
<collision>
<origin xyz="0 0.0 0" rpy="0 0 1.571" />
    <geometry>
    <cylinder length="0.001" radius="0.001" />
    </geometry>
</collision>
</link>


<joint
    name="shoulder_xrj" type="revolute">
    <origin xyz="0 0 0" rpy="0 0 0" />
    <parent link="shoulder_zr" />
    <child link="shoulder_xr" />
    <axis xyz="1 0 0" />
    <limit lower="-0.1" upper="1.6" effort="20" velocity="3"/>
</joint>

<link name="shoulder_xr">
<inertial>
    <origin xyz="0.0 0.0 0.0" rpy="0 0 0" />
    <mass value="0.1" />
    <inertia ixx="0.000000001" ixy="0.000000001" ixz="0.000000001" iyy="0.000000001" iyz="0.000000001" izz="0.000000001"/>
</inertial>
<visual>
    <origin xyz="0 0 0" rpy="0 0 1.571" />
    <geometry>
    <cylinder length="0.001" radius="0.001" />
    </geometry>
</visual>
<collision>
<origin xyz="0 0.0 0" rpy="0 0 1.571" />
    <geometry>
    <cylinder length="0.001" radius="0.001" />
    </geometry>
</collision>
</link>


<joint
    name="shoulder_yrj" type="revolute">
    <origin xyz="0 0 0" rpy="0 0 3.142" />
    <parent link="shoulder_xr" />
    <child link="right_shoulder" />
    <axis xyz="0 1 0" />
    <limit lower="0" upper="3" effort="20" velocity="3"/>
</joint>


<link name="right_shoulder">
<inertial>
    <origin xyz="0.0 0.0 0.0" rpy="0 0 0" />
    <mass value="0.1" />
    <inertia ixx="0.030306" ixy="1.072426" ixz="-0.00014" iyy="0.123799" iyz="-3.24634" izz="0.10389"/>

</inertial>
<visual>
    <origin xyz="0 0 0" rpy="1.571 0 1.571" />
    <geometry>
    <mesh filename="package://rl_walker_description/meshes/dae/arm.dae" scale="1 1 1" />
    </geometry>
</visual>
<collision>
<origin xyz="0 0.0 0" rpy="1.571 0 1.571" />
    <geometry>
    <mesh filename="package://rl_walker_description/meshes/dae/arm.dae" scale="1 1 1" />
    </geometry>
</collision>
</link>



<joint
    name="forearm_yrj" type="revolute">
    <origin xyz="0 0.48 0" rpy="0 0 3.142" />
    <parent link="right_shoulder" />
    <child link="right_forearm" />
    <axis xyz="1 0 0" />
    <limit lower="-1.6" upper="0" effort="20" velocity="3"/>
</joint>


<link name="right_forearm">
<inertial>
    <origin xyz="0.0 0.0 0.0" rpy="0 0 0" />
    <mass value="0.1" />
    <inertia ixx="0.37633" ixy="-5.2759" ixz="-8.13739" iyy="0.382769" iyz="-0.00136" izz="0.03977"/>
</inertial>
<visual>
    <origin xyz="0 0 0" rpy="0 0 0" />
    <geometry>
    <mesh filename="package://rl_walker_description/meshes/dae/forearm.dae" scale="1 1 1" />
    </geometry>
</visual>
<collision>
<origin xyz="0 0.0 0" rpy="0 0 0" />
    <geometry>
    <mesh filename="package://rl_walker_description/meshes/dae/forearm.dae" scale="1 1 1" />
    </geometry>
</collision>
</link> -->


<!-- ##########################################################
     ######################### right left ########################
     ########################################################## -->

<!-- <joint
    name="shoulder_zlj" type="revolute">
    <origin xyz="0 0.3 0.87" rpy="0 0 3.142" />
    <parent link="base_body" />
    <child link="shoulder_zl" />
    <axis xyz="0 0 1" />
    <limit lower="-1.65" upper="0.1" effort="20" velocity="3"/>
</joint>

<link name="shoulder_zl">
<inertial>
    <origin xyz="0.0 0.0 0.0" rpy="0 0 0" />
    <mass value="0.1" />
    <inertia ixx="0.000000001" ixy="0.000000001" ixz="0.000000001" iyy="0.000000001" iyz="0.000000001" izz="0.000000001"/>
</inertial>
<visual>
    <origin xyz="0 0 0" rpy="0 0 1.571" />
    <geometry>
    <cylinder length="0.001" radius="0.001" />
    </geometry>
</visual>
<collision>
<origin xyz="0 0.0 0" rpy="0 0 1.571" />
    <geometry>
    <cylinder length="0.001" radius="0.001" />
    </geometry>
</collision>
</link>


<joint
    name="shoulder_xlj" type="revolute">
    <origin xyz="0 0 0" rpy="0 0 0" />
    <parent link="shoulder_zl" />
    <child link="shoulder_xl" />
    <axis xyz="1 0 0" />
    <limit lower="-0.1" upper="1.6" effort="20" velocity="3"/>
</joint>

<link name="shoulder_xl">
<inertial>
    <origin xyz="0.0 0.0 0.0" rpy="0 0 0" />
    <mass value="0.1" />
    <inertia ixx="0.000000001" ixy="0.000000001" ixz="0.000000001" iyy="0.000000001" iyz="0.000000001" izz="0.000000001"/>
</inertial>
<visual>
    <origin xyz="0 0 0" rpy="0 0 1.571" />
    <geometry>
    <cylinder length="0.001" radius="0.001" />
    </geometry>
</visual>
<collision>
<origin xyz="0 0.0 0" rpy="0 0 1.571" />
    <geometry>
    <cylinder length="0.001" radius="0.001" />
    </geometry>
</collision>
</link> 


<joint
    name="shoulder_ylj" type="revolute">
    <origin xyz="0 0 0" rpy="0 0 3.142" />
    <parent link="shoulder_xl" />
    <child link="left_shoulder" />
    <axis xyz="0 1 0" />
    <limit lower="-3" upper="0" effort="20" velocity="3"/>
</joint>


<link name="left_shoulder">
<inertial>
    <origin xyz="0.0 0.0 0.0" rpy="0 0 0" />
    <mass value="0.1" />
    <inertia ixx="0.030306" ixy="1.072426" ixz="-0.00014" iyy="0.123799" iyz="-3.24634" izz="0.10389"/>
</inertial>
<visual>
    <origin xyz="0 0 0" rpy="1.571 0 1.571" />
    <geometry>
    <mesh filename="package://rl_walker_description/meshes/dae/arm.dae" scale="1 1 1" />
    </geometry>
</visual>
<collision>
<origin xyz="0 0.0 0" rpy="1.571 0 1.571" />
    <geometry>
    <mesh filename="package://rl_walker_description/meshes/dae/arm.dae" scale="1 1 1" />
    </geometry>
</collision>
</link>




<joint
    name="forearm_ylj" type="revolute">
    <origin xyz="0 0.48 0" rpy="0 0 3.142" />
    <parent link="left_shoulder" />
    <child link="left_forearm" />
    <axis xyz="1 0 0" />
    <limit lower="-1.6" upper="0" effort="20" velocity="3"/>
</joint>


<link name="left_forearm">
<inertial>
    <origin xyz="0.0 0.0 0.0" rpy="0 0 0" />
    <mass value="0.1" />
    <inertia ixx="0.37633" ixy="-5.2759" ixz="-8.13739" iyy="0.382769" iyz="-0.00136" izz="0.03977"/>
</inertial>
<visual>
    <origin xyz="0 0 0" rpy="0 0 3.142" />
    <geometry>
    <mesh filename="package://rl_walker_description/meshes/dae/forearm.dae" scale="1 1 1" />
    </geometry>
</visual>
<collision>
<origin xyz="0 0.0 0" rpy="0 0 3.142" />
    <geometry>
    <mesh filename="package://rl_walker_description/meshes/dae/forearm.dae" scale="1 1 1" />
    </geometry>
</collision>
</link> -->

</robot>